/home/youssef/Projects/Database/FrontEndOTC/app.py:5: MovedIn20Warning: The ``declarative_base()`` function is now available as sqlalchemy.orm.declarative_base(). (deprecated since: 2.0) (Background on SQLAlchemy 2.0 at: https://sqlalche.me/e/b8d9)
  Base = declarative_base()
2023-10-08 20:23:08,056 INFO sqlalchemy.engine.Engine BEGIN (implicit)
2023-10-08 20:23:08,057 INFO sqlalchemy.engine.Engine SELECT "Products".id AS "Products_id", "Products".name AS "Products_name" 
FROM "Products"
2023-10-08 20:23:08,057 INFO sqlalchemy.engine.Engine [generated in 0.00011s] ()
Traceback (most recent call last):
  File "/home/youssef/Projects/Database/FrontEndOTC/otc-env/lib/python3.11/site-packages/sqlalchemy/engine/base.py", line 1965, in _exec_single_context
    self.dialect.do_execute(
  File "/home/youssef/Projects/Database/FrontEndOTC/otc-env/lib/python3.11/site-packages/sqlalchemy/engine/default.py", line 921, in do_execute
    cursor.execute(statement, parameters)
sqlite3.OperationalError: no such column: Products.name

The above exception was the direct cause of the following exception:

Traceback (most recent call last):
  File "/home/youssef/Projects/Database/FrontEndOTC/app.py", line 22, in <module>
    products = session.query(Product).all()
               ^^^^^^^^^^^^^^^^^^^^^^^^^^^^
  File "/home/youssef/Projects/Database/FrontEndOTC/otc-env/lib/python3.11/site-packages/sqlalchemy/orm/query.py", line 2688, in all
    return self._iter().all()  # type: ignore
           ^^^^^^^^^^^^
  File "/home/youssef/Projects/Database/FrontEndOTC/otc-env/lib/python3.11/site-packages/sqlalchemy/orm/query.py", line 2842, in _iter
    result: Union[ScalarResult[_T], Result[_T]] = self.session.execute(
                                                  ^^^^^^^^^^^^^^^^^^^^^
  File "/home/youssef/Projects/Database/FrontEndOTC/otc-env/lib/python3.11/site-packages/sqlalchemy/orm/session.py", line 2262, in execute
    return self._execute_internal(
           ^^^^^^^^^^^^^^^^^^^^^^^
  File "/home/youssef/Projects/Database/FrontEndOTC/otc-env/lib/python3.11/site-packages/sqlalchemy/orm/session.py", line 2144, in _execute_internal
    result: Result[Any] = compile_state_cls.orm_execute_statement(
                          ^^^^^^^^^^^^^^^^^^^^^^^^^^^^^^^^^^^^^^^^
  File "/home/youssef/Projects/Database/FrontEndOTC/otc-env/lib/python3.11/site-packages/sqlalchemy/orm/context.py", line 293, in orm_execute_statement
    result = conn.execute(
             ^^^^^^^^^^^^^
  File "/home/youssef/Projects/Database/FrontEndOTC/otc-env/lib/python3.11/site-packages/sqlalchemy/engine/base.py", line 1412, in execute
    return meth(
           ^^^^^
  File "/home/youssef/Projects/Database/FrontEndOTC/otc-env/lib/python3.11/site-packages/sqlalchemy/sql/elements.py", line 516, in _execute_on_connection
    return connection._execute_clauseelement(
           ^^^^^^^^^^^^^^^^^^^^^^^^^^^^^^^^^^
  File "/home/youssef/Projects/Database/FrontEndOTC/otc-env/lib/python3.11/site-packages/sqlalchemy/engine/base.py", line 1635, in _execute_clauseelement
    ret = self._execute_context(
          ^^^^^^^^^^^^^^^^^^^^^^
  File "/home/youssef/Projects/Database/FrontEndOTC/otc-env/lib/python3.11/site-packages/sqlalchemy/engine/base.py", line 1844, in _execute_context
    return self._exec_single_context(
           ^^^^^^^^^^^^^^^^^^^^^^^^^^
  File "/home/youssef/Projects/Database/FrontEndOTC/otc-env/lib/python3.11/site-packages/sqlalchemy/engine/base.py", line 1984, in _exec_single_context
    self._handle_dbapi_exception(
  File "/home/youssef/Projects/Database/FrontEndOTC/otc-env/lib/python3.11/site-packages/sqlalchemy/engine/base.py", line 2339, in _handle_dbapi_exception
    raise sqlalchemy_exception.with_traceback(exc_info[2]) from e
  File "/home/youssef/Projects/Database/FrontEndOTC/otc-env/lib/python3.11/site-packages/sqlalchemy/engine/base.py", line 1965, in _exec_single_context
    self.dialect.do_execute(
  File "/home/youssef/Projects/Database/FrontEndOTC/otc-env/lib/python3.11/site-packages/sqlalchemy/engine/default.py", line 921, in do_execute
    cursor.execute(statement, parameters)
sqlalchemy.exc.OperationalError: (sqlite3.OperationalError) no such column: Products.name
[SQL: SELECT "Products".id AS "Products_id", "Products".name AS "Products_name" 
FROM "Products"]
(Background on this error at: https://sqlalche.me/e/20/e3q8)
